Workbook

Sheet Cover Page
B3: Stephen Dornu Dugbartey
B4: Edmonton, Alberta - Canada | +1 (825) 777-0501 | ddstephen07@gmail.com
B6: Project: Financial Statement Analysis
B10: Sections:
C11: Part 1: Horizontal and Vertical Analysis
C12: Part 2: Ratio Analysis
B13: References:
C14: Albrecht and Al. (2019). Fraud Examination. 6th Ed. South-Western. ISBN: 978-1-337-61967-7 pg 191, 194, 195

Sheet Part 1
A2: ABC COMPANY
A3: BALANCE SHEET
A4: AS OF DECEMBER 31, 2018
C6: Vertical Analysis of the Balance Sheet | I6: Redflags | J6: Comments on Redflags
A7: ASSETS | C7: 2018 | D7: % Change | E7: 2017 | F7: % Change | G7: 2016 | H7: % Change
A8: Current assets | C8: $ | E8: $ | G8: $ | J8: Six (1 to 6) red flags have been identified with the vertical analysis of the ABC Company Balance Sheet. Since the current assets makes 75% in 2018, 73% in 2017 and 67% in 2016 of the total assets of the balance sheet, our interest as a team was drawn to the highest contributors to the current assets as red flags for enquiry. Cash (1), account receivable (2), inventory (3), and prepaid expenses (4) have to be broken down and understood. For cash: locations of cash between bank deposits, and cash held at the premises has to be understood; for account receivable: the ages of receivable and their exposed amounts has to be understood; for inventory: their availability, condition, ages and amounts held with the ages has to be understood; prepaid expenses: reasons for committing between 9% and 12% of total assets in line with company policy and approvals has to be understood. The accounts payable and accrued liabilities are the highest contributors to the current liabilities of the balance sheet. They create concern for further enquiry. The classes of the liabilities, their ageing should be understood in line with company policy and agreement with vendors.
B9: Cash | C9: 501992 | D9: =C9/$C$16 -> 0.23334974 | E9: 434215 | F9: =E9/$E$16 -> 0.21582989 | G9: 375141 | H9: =G9/$G$16 -> 0.23535896 | I9: 1
B10: Accounts receivable | C10: 335272 | D10: =C10/$C$16 -> 0.15585036 | E10: 302514 | F10: =E10/$E$16 -> 0.1503669 | G10: 241764 | H10: =G10/$G$16 -> 0.15167983 | I10: 2
B11: Inventory | C11: 515174 | D11: =C11/$C$16 -> 0.23947736 | E11: 505321 | F11: =E11/$E$16 -> 0.25117368 | G11: 310885 | H11: =G11/$G$16 -> 0.19504552 | I11: 3
B12: Prepaid expenses | C12: 251874 | D12: =C12/$C$16 -> 0.11708301 | E12: 231100 | F12: =E12/$E$16 -> 0.11487003 | G12: 136388 | H12: =G12/$G$16 -> 0.085568194 | I12: 4
B13: Total current assets | C13: =SUM(C9:C12) -> 1604312 | D13: =C13/$C$16 -> 0.74576047 | E13: =SUM(E9:E12) -> 1473150 | F13: =E13/$E$16 -> 0.7322405 | G13: =SUM(G9:G12) -> 1064178 | H13: =G13/$G$16 -> 0.6676525
A14: Property, plant, and equipment | C14: 765215 | D14: =C14/$C$16 -> 0.3557083 | E14: 735531 | F14: =E14/$E$16 -> 0.36560132 | G14: 705132 | H14: =G14/$G$16 -> 0.44239135
A15: Accumulated depreciation | C15: -218284 | D15: =C15/$C$16 -> -0.10146878 | E15: -196842 | F15: =E15/$E$16 -> -0.097841825 | G15: -175400 | H15: =G15/$G$16 -> -0.11004385
A16: Total Assets | C16: =C13+C14+C15 -> 2151243 | D16: =C16/$C$16 -> 1 | E16: =E13+E14+E15 -> 2011839 | F16: =E16/$E$16 -> 1 | G16: =G13+G14+G15 -> 1593910 | H16: =G16/$G$16 -> 1
A18: LIABILITIES
A19: Current liabilities
B20: Accounts payable | C20: 248494 | D20: =C20/$C$34 -> 0.11551182 | E20: 366864 | F20: =E20/$E$34 -> 0.18235256 | G20: 322156 | H20: =G20/$G$34 -> 0.20211681 | I20: 5
B21: Accrued liabilities | C21: 122192 | D21: =C21/$C$34 -> 0.05680065 | E21: 216533 | F21: =E21/$E$34 -> 0.10762939 | G21: 215474 | H21: =G21/$G$34 -> 0.1351858 | I21: 6
B22: Income taxes payable | C22: 10645 | D22: =C22/$C$34 -> 0.004948302 | E22: 25698 | F22: =E22/$E$34 -> 0.012773388 | G22: 22349 | H22: =G22/$G$34 -> 0.014021494
B23: Current portion of long-term debt | C23: 42200 | D23: =C23/$C$34 -> 0.019616566 | E23: 42200 | F23: =E23/$E$34 -> 0.020975834 | G23: 42200 | H23: =G23/$G$34 -> 0.026475773
B24: Total current liabilities | C24: =SUM(C20:C23) -> 423531 | D24: =C24/$C$34 -> 0.19687734 | E24: =SUM(E20:E23) -> 651295 | F24: =E24/$E$34 -> 0.32373117 | G24: =SUM(G20:G23) -> 602179 | H24: =G24/$G$34 -> 0.37779988
A25: Long-term liabilities | D25: =C25/$C$34 -> 0 | F25: =E25/$E$34 -> 0 | H25: =G25/$G$34 -> 0
B26: Long-term debt | C26: 425311 | D26: =C26/$C$34 -> 0.19770477 | E26: 400311 | F26: =E26/$E$34 -> 0.19897765 | G26: 375100 | H26: =G26/$G$34 -> 0.23533324
A27: Total Liabilities | C27: =C24+C26 -> 848842 | D27: =C27/$C$34 -> 0.39458211 | E27: =E24+E26 -> 1051606 | F27: =E27/$E$34 -> 0.52270883 | G27: =G24+G26 -> 977279 | H27: =G27/$G$34 -> 0.61313311
A29: STOCKHOLDERS' EQUITY
A30: Common stock | C30: 370124 | D30: =C30/$C$34 -> 0.17205123 | E30: 356758 | F30: =E30/$E$34 -> 0.1773293 | G30: 320841 | H30: =G30/$G$34 -> 0.20129179
A31: Additional paid-in capital | C31: 29546 | D31: =C31/$C$34 -> 0.013734385 | E31: 24881 | F31: =E31/$E$34 -> 0.012367292 | G31: 21910 | H31: =G31/$G$34 -> 0.013746071
A32: Retained earnings | C32: 902731 | D32: =C32/$C$34 -> 0.41963228 | E32: 578594 | F32: =E32/$E$34 -> 0.28759458 | G32: 273880 | H32: =G32/$G$34 -> 0.17182902
B33: Total stockholders' equity | C33: 1302401 | D33: =C33/$C$34 -> 0.60541789 | E33: 960233 | F33: =E33/$E$34 -> 0.47729117 | G33: 616631 | H33: =G33/$G$34 -> 0.38686689
A34: Total Liabilities and Stockholders Equity | C34: 2151243 | D34: =C34/$C$34 -> 1 | E34: 2011839 | F34: =E34/$E$34 -> 1 | G34: 1593910 | H34: =G34/$G$34 -> 1
A40: ABC COMPANY
A41: INCOME STATEMENT
A42: FOR THE PERIOD ENDED DECEMBER 31, 2018
C43: 2018 | D43: 2017 | E43: 2016 | F43: Horizontal Analysis of the Income Statement
F44: 2018 | H44: 2017 | K44: Comments on Redflags
C45: $ | D45: $ | E45: $ | F45: Amount Change | G45: % Change | H45: Amount Change | I45: % Change | J45: Redflags
A46: Sales | C46: 1572134 | D46: 1413581 | E46: 1158417 | F46: =C46-D46 -> 158553 | G46: =F46/D46 -> 0.11216407 | H46: =D46-E46 -> 255164 | I46: =H46/E46 -> 0.22026956 | K46: Five red flags (1 to 5), have been identified with the horizontal analysis of ABC Company income statement to be further queried or investigated if evidence shows same. The advertising (1), legal (2) and miscellaneous (3) expenses have sky rocketed from 20%, 5% and 7% of gross sales value respectively in 2017 to 999%, 69% and 192% of gross sales value respectively in 2018. The reasons, approvals and source documents should be required. The salaries and wages (4) have reduced tremendously from 16% to 4% of gross sales value. Clarity should be sought from management. The sum of the total expenses (5) in the income statement published by management of ABC Company was incorrect; published as $430,690 instead of $930,690. Therefore, total expenses value was underestimated by $500,000, hence overstating the net income by $500,000.
A47: Cost of goods sold | C47: 601215 | D47: 556721 | E47: 500702 | F47: =C47-D47 -> 44494 | G47: =F47/D47 -> 0.079921541 | H47: =D47-E47 -> 56019 | I47: =H47/E47 -> 0.11188092
A48: Gross Profit | C48: =C46-C47 -> 970919 | D48: =D46-D47 -> 856860 | E48: =E46-E47 -> 657715 | F48: =C48-D48 -> 114059 | G48: =F48/D48 -> 0.13311276 | H48: =D48-E48 -> 199145 | I48: =H48/E48 -> 0.30278312
A50: EXPENSES
...

Sheet Part 2
A1: ABC COMPANY
A2: RATIO ANALYSIS
A3: DEMCEBER 31, 2018
A4: LIQUIDITY RATIOS | C4: 2018 | D4: 2017 | E4: Change | F4: % Change | G4: Redflags | H4: Comments on Redflags
B5: Current ratio | C5: ='Part 1'!C13/'Part 1'!C24 -> 3.7879447 | D5: ='Part 1'!E13/'Part 1'!E24 -> 2.2618783 | E5: =C5-D5 -> 1.5260664 | F5: =E5/D5 -> 0.6746899 | H5: Three (1 to 3) red flags have been identified with the ratio analysis of ABC Company Income Statement and Balance Sheet. The owner’s equity in relation to the total assets increased from 47.73% to 60.54%. There is a concern to show proof of the owner’s new contribution that caused the increase. The current liabilities and total liabilities in relation to the owners’ equity fell drastically from 67.86% and 109.52% respectively to 32.52 to 65.18% respectively. There is a concern to show proof of settling the liabilities against possible cosmetic accounting reasons of the company which caused the reductions.
B6: Quick ratio | C6: =('Part 1'!C13-'Part 1'!C11)/'Part 1'!C24 -> 2.5715662 | D6: =('Part 1'!E13-'Part 1'!E11)/'Part 1'!E24 -> 1.4860071 | E6: =C6-D6 -> 1.0855591 | F6: =E6/D6 -> 0.73052079
B7: Account receivable turnover | C7: ='Part 1'!C46/318893 -> 4.9299734 | D7: ='Part 1'!D46/272139 -> 5.1943345 | E7: =C7-D7 -> -0.26436114 | F7: =E7/D7 -> -0.05089413
B8: Days' sales in account receivable | C8: =365/C7 -> 74.036911 | D8: =365/D7 -> 70.268867 | E8: =C8-D8 -> 3.7680442 | F8: =E8/D8 -> 0.053623238
B9: Inventory turnover | C9: =('Part 1'!C47/('Part 1'!C11+'Part 1'!E11)/2) -> 0.29457028 | D9: =('Part 1'!D47/('Part 1'!E11+'Part 1'!G11)/2) -> 0.34104197 | E9: =C9-D9 -> -0.046471685 | F9: =E9/D9 -> -0.13626383
A11: PROFITABILITY / PERFORMANCE RATIOS
B12: Profit margin | C12: =C47/C30 -> 0.20617645 | D12: =D47/D30 -> 0.21556175 | E12: =C12-D12 -> -0.0093853086 | F12: =E12/D12 -> -0.04353884
B13: Gross profit margin (%) | C13: ='Part 1'!C48/'Part 1'!C46 -> 0.61758031 | D13: ='Part 1'!D48/'Part 1'!D46 -> 0.60616265 | E13: =C13-D13 -> 0.011417662 | F13: =E13/D13 -> 0.01883597
B14: Earning per share | C14: =C47/C49 -> 9.0256175 | D14: ='Part 1'!D63/'Part 1'!D65 -> 11.375868 | E14: =C14-D14 -> -2.3502505 | F14: =E14/D14 -> -0.20659967
B15: Sales/Total assets | C15: ='Part 1'!C46/'Part 1'!C16 -> 0.73080261 | D15: ='Part 1'!D46/'Part 1'!E16 -> 0.70263127 | E15: =C15-D15 -> 0.028171336 | F15: =E15/D15 -> 0.040094054
B16: Sales/Working capital | C16: ='Part 1'!C46/('Part 1'!C13-'Part 1'!C24) -> 1.3314357 | D16: ='Part 1'!D46/('Part 1'!E13-'Part 1'!E24) -> 1.7199883 | E16: =C16-D16 -> -0.3885526 | F16: =E16/D16 -> -0.22590421
A18: EQUITY POSITION RATIOS
B19: Owners' equity/Total assets | C19: ='Part 1'!C33/'Part 1'!C16 -> 0.60541789 | D19: ='Part 1'!E33/'Part 1'!E16 -> 0.47729117 | E19: =C19-D19 -> 0.12812672 | F19: =E19/D19 -> 0.2684456 | G19: 1
B20: Current liabilities/Owners' equity | C20: ='Part 1'!C24/'Part 1'!C33 -> 0.32519247 | D20: ='Part 1'!E24/'Part 1'!E33 -> 0.67826767 | E20: =C20-D20 -> -0.3530752 | F20: =E20/D20 -> -0.52055437 | G20: 2
B21: Total liabilities/Owners' equity | C21: ='Part 1'!C27/'Part 1'!C33 -> 0.65175165 | D21: ='Part 1'!E27/'Part 1'!E33 -> 1.0951571 | E21: =C21-D21 -> -0.44340546 | F21: =E21/D21 -> -0.4048784 | G21: 3
A24: ABC COMPANY
A25: INCOME STATEMENT
A26: FOR THE PERIOD ENDED DECEMBER 31, 2018
C27: 2018 | D27: 2017 | E27: 2016
C29: $ | D29: $ | E29: $
A30: Sales | C30: 1572134 | D30: 1413581 | E30: 1158417
A31: Cost of goods sold | C31: 601215 | D31: 556721 | E31: 500702
A32: Gross Profit | C32: =C30-C31 -> 970919 | D32: =D30-D31 -> 856860 | E32: =E30-E31 -> 657715
A34: EXPENSES
B35: Advertising | C35: 55153 | D35: 50531 | E35: 42150
B36: Depreciation | C36: 21442 | D36: 21442 | E36: 21442
B37: Bad debts | C37: 20151 | D37: 18934 | E37: 17943
B38: Legal | C38: 17261 | D38: 10207 | E38: 9701
B39: Miscellaneous | C39: 91014 | D39: 31214 | E39: 29104
B40: Rent | C40: 148321 | D40: 142078 | E40: 141143
B41: Repairs and maintenance | C41: 14315 | D41: 13642 | E41: 11932
B42: Salaries and wages | C42: 47121 | D42: 45312 | E42: 39142
B43: Utilities | C43: 15912 | D43: 15643 | E43: 14217
A44: Total Expenses | C44: =SUM(C35:C43) -> 430690 | D44: =SUM(D35:D43) -> 349003 | E44: =SUM(E35:E43) -> 326774
A45: Net Income before income tax | C45: =C32-C44 -> 540229 | D45: =D32-D44 -> 507857 | E45: =E32-E44 -> 330941
A46: Income tax expenses | C46: 216092 | D46: 203143 | E46: 132376
...
